from django.core.exceptions import ValidationError
from django.utils import timezone
from django.db import models  # âœ… This import is required
from django.contrib.auth.models import User

class Todo(models.Model):
    user = models.ForeignKey(User, on_delete=models.CASCADE)
    title = models.CharField(max_length=200)
    completed = models.BooleanField(default=False)
    due_date = models.DateField(null=True, blank=True)


    def clean(self):
        if self.due_date and self.due_date < timezone.now().date():
            raise ValidationError("Due date cannot be in the past.")

    def __str__(self):
        return self.title

class Task(models.Model):
    user = models.ForeignKey(User, on_delete=models.CASCADE)
    title = models.CharField(max_length=200)
    description = models.TextField(blank=True)
    due_date = models.DateTimeField()
    completed = models.BooleanField(default=False)

    def __str__(self):
        return self.title